Workbook

Sheet Leia-me
A1: AtlasPen — auditoria por amostra: fichas e apuração
A2: Protocolo: AUDITORIA.md · versão auditada: commit 26742210c50e5ccdebfbd99b68784fa4ac70333d · amostra gerada em 2026-09-28
A3: 100 fichas para o Revisor A; 20 delas (em amarelo) também para o Revisor B, que não vê a ficha de A.
A5: Como preencher
A6: 1. Abra o link do compilado e leia o dispositivo indicado — o caput e os parágrafos que ele cita. Não consulte o site do AtlasPen: a ficha é cega de propósito, e ver o valor publicado induz a confirmá-lo.
A7: 2. Preencha os nove campos com o que A LEI diz. Pena mínima e máxima em MESES inteiros (1 ano = 12; 2 anos e 6 meses = 30; se a lei não fixa mínimo, escreva 0). Onde há lista suspensa, escolha um valor.
A8: 3. 'Hediondo' pede o rol do art. 1º da Lei 8.072/90, inclusive equiparados (CF, art. 5º, XLIII). 'Violência' e 'grave ameaça' são a violência DOLOSA contra pessoa e a ameaça como meio ou núcleo do tipo. 'Elemento subjetivo' segue a régua do projeto: doloso, culposo, preterdoloso, ou qualificado pelo resultado.
A9: 4. Quando o compilado não permitir decidir um campo, ou permitir mais de uma leitura, NÃO chute: escreva na coluna 'ressalvas' no formato campo: fonte insuficiente — motivo ou campo: juízo discutível — qual leitura e por quê. Uma ressalva por linha.
A10: 5. Anote o tempo gasto na ficha, em minutos. Serve para calibrar a fase 2 do protocolo.
A11: 6. Só DEPOIS de preencher a aba 'Fichas', abra 'Nomes e vigência': lá estão o nome publicado e a vigência, para você dizer se conferem com o que leu.
A12: 7. Linha destacada em amarelo está na subamostra de dupla conferência: se houver segunda pessoa, ela lê só essas, na aba Revisor B, sem ver a ficha da primeira.
A14: O que acontece depois
... A20: Nada aqui é lido pelo AtlasPen automaticamente: a apuração de referência é o scripts/auditoria/apurar.py, que dá os mesmos números. A planilha existe para que a conferência se veja enquanto se faz.

Sheet Revisor A
A1: id | B1: diploma | C1: dispositivo | D1: link do compilado | E1: dupla | F1: pena mínima (meses) | G1: ressalva | H1: pena máxima (meses) | I1: ressalva | J1: espécie de pena | K1: ressalva | L1: hediondo | M1: ressalva | N1: violência | O1: ressalva | P1: grave ameaça | Q1: ressalva | R1: elemento subjetivo | S1: ressalva | T1: admite tentativa | U1: ressalva | V1: ação penal | W1: ressalva | X1: tempo (min) | Y1: observações | Z1: nome publicado | AA1: vigente (publicado) | AB1: nome confere? | AC1: vigência confere?
A2: 165 | B2: CP | C2: Art. 211 | D2: https://www.planalto.gov.br/ccivil_03/decreto-lei/del2848compilado.htm | E2: sim | Z2: Destruição, subtração ou ocultação de cadáver | AA2: Sim
A3: 1335 | B3: CP | C3: Art. 254 (no caso de culpa) | D3: https://www.planalto.gov.br/ccivil_03/decreto-lei/del2848compilado.htm | E3: sim | Z3: Inundação — modalidade culposa | AA3: Sim
A4: 172 | B4: CP | C4: Art. 235 | D4: https://www.planalto.gov.br/ccivil_03/decreto-lei/del2848compilado.htm | E4: sim | Z4: Bigamia | AA4: Sim
A5: 994 | B5: CP | C5: Art. 162, caput | D5: https://www.planalto.gov.br/ccivil_03/decreto-lei/del2848compilado.htm | E5: sim | Z5: Alteração de marca ou sinal indicativo de propriedade de gado ou rebanho | AA5: Sim
A6: 70 | B6: CP | C6: Art. 148, §1º | D6: https://www.planalto.gov.br/ccivil_03/decreto-lei/del2848compilado.htm | E6: sim | Z6: Sequestro qualificado (fins libidinosos, menor de 18, maus-tratos, mais de 15 dias) | AA6: Sim
A7: 66 | B7: CP | C7: Art. 147 | D7: https://www.planalto.gov.br/ccivil_03/decreto-lei/del2848compilado.htm | E7: sim | Z7: Ameaça | AA7: Sim
A8: 280 | B8: CP | C8: Art. 342 | D8: https://www.planalto.gov.br/ccivil_03/decreto-lei/del2848compilado.htm | Z8: Falso testemunho ou falsa perícia | AA8: Sim
A9: 231 | B9: CP | C9: Art. 297 | D9: https://www.planalto.gov.br/ccivil_03/decreto-lei/del2848compilado.htm | Z9: Falsificação de documento público | AA9: Sim
A10: 1379 | B10: CP | C10: Art. 348, §1º | D10: https://www.planalto.gov.br/ccivil_03/decreto-lei/del2848compilado.htm | Z10: Favorecimento pessoal — Se ao crime não é cominada pena de reclusão | AA10: Sim
A11: 153 | B11: CP | C11: Art. 199 | D11: https://www.planalto.gov.br/ccivil_03/decreto-lei/del2848compilado.htm | Z11: Atentado contra a liberdade de associação | AA11: Sim
A12: 275 | B12: CP | C12: Art. 337-B | D12: https://www.planalto.gov.br/ccivil_03/decreto-lei/del2848compilado.htm | Z12: Corrupção ativa em transação comercial internacional | AA12: Sim
A13: 1375 | B13: CP | C13: Art. 337-M | D13: https://www.planalto.gov.br/ccivil_03/decreto-lei/del2848compilado.htm | Z13: Contratação inidônea | AA13: Sim
A14: 186 | B14: CP | C14: Art. 250, §2º | D14: https://www.planalto.gov.br/ccivil_03/decreto-lei/del2848compilado.htm | Z14: Incêndio culposo | AA14: Sim
A15: 49 | B15: CP | C15: Art. 133, §2º | D15: https://www.planalto.gov.br/ccivil_03/decreto-lei/del2848compilado.htm | Z15: Abandono de incapaz com resultado morte | AA15: Sim
A16: 213 | B16: CP | C16: Art. 278 | D16: https://www.planalto.gov.br/ccivil_03/decreto-lei/del2848compilado.htm | Z16: Outras substâncias nocivas à saúde pública | AA16: Sim
A17: 151 | B17: CP | C17: Art. 197, I | D17: https://www.planalto.gov.br/ccivil_03/decreto-lei/del2848compilado.htm | Z17: Atentado contra a liberdade de trabalho — profissão ou trabalho | AA17: Sim
A18: 1338 | B18: CP | C18: Art. 134, §1º | D18: https://www.planalto.gov.br/ccivil_03/decreto-lei/del2848compilado.htm | Z18: Exposição ou abandono de recém-nascido — lesão grave | AA18: Sim
A19: 294 | B19: CP | C19: Art. 356 | D19: https://www.planalto.gov.br/ccivil_03/decreto-lei/del2848compilado.htm | Z19: Sonegação de papel ou objeto de valor probatório por advogado ou procurador | AA19: Sim
... A35: 12 | B35: CP | C35: Art. 121, §4º, 1ª parte | D35: https://www.planalto.gov.br/ccivil_03/decreto-lei/del2848compilado.htm | Z35: Homicídio culposo com aumento de 1/3 (inobservância de regra técnica) | AA35: Sim
A36: 706 | B36: CPM (DL 1.001/69) | C36: Art. 291, caput | D36: https://www.planalto.gov.br/ccivil_03/decreto-lei/del1001compilado.htm | E36: sim | Z36: Receita ilegal | AA36: Sim
A37: 1196 | B37: CPM (DL 1.001/69) | C37: Art. 326, caput | D37: https://www.planalto.gov.br/ccivil_03/decreto-lei/del1001compilado.htm | E37: sim | Z37: Violação de sigilo funcional | AA37: Sim
A38: 1108 | B38: CPM (DL 1.001/69) | C38: Art. 235, caput | D38: https://www.planalto.gov.br/ccivil_03/decreto-lei/del1001compilado.htm | E38: sim | Z38: Ato de libidinagem | AA38: Sim
A39: 1050 | B39: CPM (DL 1.001/69) | C39: Art. 172, caput | D39: https://www.planalto.gov.br/ccivil_03/decreto-lei/del1001compilado.htm | E39: sim | Z39: Uso indevido de uniforme, distintivo ou insígnia militar por qualquer pessoa | AA39: Sim
A40: 1383 | B40: CPM (DL 1.001/69) | C40: Art. 182, caput (aos cabeças) | D40: https://www.planalto.gov.br/ccivil_03/decreto-lei/del1001compilado.htm | Z40: Amotinamento (cabeça) | AA40: Sim
A41: 1026 | B41: CPM (DL 1.001/69) | C41: Art. 145, §1º | D41: https://www.planalto.gov.br/ccivil_03/decreto-lei/del1001compilado.htm | Z41: Turbação de objeto ou documento — comprometimento da segurança ou eficiência bélica | AA41: Sim
A42: 1084 | B42: CPM (DL 1.001/69) | C42: Art. 210, caput | D42: https://www.planalto.gov.br/ccivil_03/decreto-lei/del1001compilado.htm | Z42: Lesão culposa | AA42: Sim
A43: 1033 | B43: CPM (DL 1.001/69) | C43: Art. 151, caput | D43: https://www.planalto.gov.br/ccivil_03/decreto-lei/del1001compilado.htm | Z43: Omissão de lealdade militar | AA43: Sim
A44: 1182 | B44: CPM (DL 1.001/69) | C44: Art. 310, caput | D44: https://www.planalto.gov.br/ccivil_03/decreto-lei/del1001compilado.htm | Z44: Participação ilícita | AA44: Sim
A45: 1273 | B45: CPM (DL 1.001/69) | C45: Art. 393, caput | D45: https://www.planalto.gov.br/ccivil_03/decreto-lei/del1001compilado.htm | Z45: Falta de apresentação | AA45: Sim
A46: 702 | B46: CPM (DL 1.001/69) | C46: Art. 248, caput | D46: https://www.planalto.gov.br/ccivil_03/decreto-lei/del1001compilado.htm | Z46: Apropriação indébita simples | AA46: Sim
A47: 1121 | B47: CPM (DL 1.001/69) | C47: Art. 254, caput | D47: https://www.planalto.gov.br/ccivil_03/decreto-lei/del1001compilado.htm | Z47: Receptação | AA47: Sim
A48: 710 | B48: CPM (DL 1.001/69) | C48: Art. 309, caput | D48: https://www.planalto.gov.br/ccivil_03/decreto-lei/del1001compilado.htm | Z48: Corrupção ativa | AA48: Sim
A49: 707 | B49: CPM (DL 1.001/69) | C49: Art. 298, caput | D49: https://www.planalto.gov.br/ccivil_03/decreto-lei/del1001compilado.htm | Z49: Desacato a superior | AA49: Sim
A50: 1269 | B50: CPM (DL 1.001/69) | C50: Art. 389, par. único | D50: https://www.planalto.gov.br/ccivil_03/decreto-lei/del1001compilado.htm | Z50: Violência contra superior ou militar de serviço — com arma, em presença do inimigo | AA50: Sim
A51: 1070 | B51: CPM (DL 1.001/69) | C51: Art. 191, caput | D51: https://www.planalto.gov.br/ccivil_03/decreto-lei/del1001compilado.htm | Z51: Concêrto para deserção | AA51: Sim
... A55: 675 | B55: CPM (DL 1.001/69) | C55: Art. 136, caput | D55: https://www.planalto.gov.br/ccivil_03/decreto-lei/del1001compilado.htm | Z55: Hostilidade contra país estrangeiro | AA55: Sim
A56: 1437 | B56: CPM (DL 1.001/69) | C56: Art. 404 c/c art. 240, §5º | D56: https://www.planalto.gov.br/ccivil_03/decreto-lei/del1001compilado.htm | E56: sim | Z56: Furto qualificado — coisa pertencente à Fazenda Pública (tempo de guerra) | AA56: Sim
A57: 1445 | B57: CPM (DL 1.001/69) | C57: Art. 405 c/c art. 243, §1º | D57: https://www.planalto.gov.br/ccivil_03/decreto-lei/del1001compilado.htm | Z57: Extorsão qualificada (tempo de guerra) | AA57: Sim
A58: 1439 | B58: CPM (DL 1.001/69) | C58: Art. 404 c/c art. 240, §6º-A | D58: https://www.planalto.gov.br/ccivil_03/decreto-lei/del1001compilado.htm | Z58: Furto qualificado — material de uso restrito militar (tempo de guerra) | AA58: Sim
...

Sheet Revisor B
A1: id | B1: diploma | C1: dispositivo | D1: link do compilado | E1: dupla | F1: pena mínima (meses) | G1: ressalva | H1: pena máxima (meses) | I1: ressalva | J1: espécie de pena | K1: ressalva | L1: hediondo | M1: ressalva | N1: violência | O1: ressalva | P1: grave ameaça | Q1: ressalva | R1: elemento subjetivo | S1: ressalva | T1: admite tentativa | U1: ressalva | V1: ação penal | W1: ressalva | X1: tempo (min) | Y1: observações | Z1: nome publicado | AA1: vigente (publicado) | AB1: nome confere? | AC1: vigência confere?
A2: 165 | B2: CP | C2: Art. 211 | D2: https://www.planalto.gov.br/ccivil_03/decreto-lei/del2848compilado.htm | E2: sim | Z2: Destruição, subtração ou ocultação de cadáver | AA2: Sim
A3: 1335 | B3: CP | C3: Art. 254 (no caso de culpa) | D3: https://www.planalto.gov.br/ccivil_03/decreto-lei/del2848compilado.htm | E3: sim | Z3: Inundação — modalidade culposa | AA3: Sim
A4: 172 | B4: CP | C4: Art. 235 | D4: https://www.planalto.gov.br/ccivil_03/decreto-lei/del2848compilado.htm | E4: sim | Z4: Bigamia | AA4: Sim
A5: 994 | B5: CP | C5: Art. 162, caput | D5: https://www.planalto.gov.br/ccivil_03/decreto-lei/del2848compilado.htm | E5: sim | Z5: Alteração de marca ou sinal indicativo de propriedade de gado ou rebanho | AA5: Sim
A6: 70 | B6: CP | C6: Art. 148, §1º | D6: https://www.planalto.gov.br/ccivil_03/decreto-lei/del2848compilado.htm | E6: sim | Z6: Sequestro qualificado (fins libidinosos, menor de 18, maus-tratos, mais de 15 dias) | AA6: Sim
A7: 66 | B7: CP | C7: Art. 147 | D7: https://www.planalto.gov.br/ccivil_03/decreto-lei/del2848compilado.htm | E7: sim | Z7: Ameaça | AA7: Sim
A8: 706 | B8: CPM (DL 1.001/69) | C8: Art. 291, caput | D8: https://www.planalto.gov.br/ccivil_03/decreto-lei/del1001compilado.htm | E8: sim | Z8: Receita ilegal | AA8: Sim
A9: 1196 | B9: CPM (DL 1.001/69) | C9: Art. 326, caput | D9: https://www.planalto.gov.br/ccivil_03/decreto-lei/del1001compilado.htm | E9: sim | Z9: Violação de sigilo funcional | AA9: Sim
A10: 1108 | B10: CPM (DL 1.001/69) | C10: Art. 235, caput | D10: https://www.planalto.gov.br/ccivil_03/decreto-lei/del1001compilado.htm | E10: sim | Z10: Ato de libidinagem | AA10: Sim
A11: 1050 | B11: CPM (DL 1.001/69) | C11: Art. 172, caput | D11: https://www.planalto.gov.br/ccivil_03/decreto-lei/del1001compilado.htm | E11: sim | Z11: Uso indevido de uniforme, distintivo ou insígnia militar por qualquer pessoa | AA11: Sim
A12: 1437 | B12: CPM (DL 1.001/69) | C12: Art. 404 c/c art. 240, §5º | D12: https://www.planalto.gov.br/ccivil_03/decreto-lei/del1001compilado.htm | E12: sim | Z12: Furto qualificado — coisa pertencente à Fazenda Pública (tempo de guerra) | AA12: Sim
A13: 1298 | B13: Lei 1.521/51 | C13: Art. 4º, b | D13: https://www.planalto.gov.br/ccivil_03/leis/l1521.htm | E13: sim | Z13: Usura real | AA13: Sim
... A21: 1320 | B21: ECA | C21: Art. 240, §1º, I | D21: https://www.planalto.gov.br/ccivil_03/leis/l8069compilado.htm | E21: sim | Z21: Agenciamento, recrutamento ou intermediação da participação de criança ou adolescente em cena de sexo explícito | AA21: Sim

Sheet Apuração A
A1: id | B1: estrato | C1: pena_min | D1: pena_max | E1: tipo_pena | F1: hediondo | G1: violencia | H1: grave_ameaca | I1: elemento | J1: tentativa | K1: acao | L1: nome | M1: vigência | N1: divergências S1 | O1: saída do registro
A2: ='Revisor A'!A2 | B2: =IFERROR(INDEX(Gabarito!$M:$M,MATCH($A2,Gabarito!$A:$A,0)),"") | C2: =IF('Revisor A'!G2<>"",'Revisor A'!G2,IF('Revisor A'!F2="","não preenchido",IF(ABS(N('Revisor A'!F2)-N(INDEX(Gabarito!$B:$B,MATCH($A2,Gabarito!$A:$A,0))))<=1,"confere","diverge"))) | D2: =IF('Revisor A'!I2<>"",'Revisor A'!I2,IF('Revisor A'!H2="","não preenchido",IF(ABS(N('Revisor A'!H2)-N(INDEX(Gabarito!$C:$C,MATCH($A2,Gabarito!$A:$A,0))))<=1,"confere","diverge"))) | E2: =IF('Revisor A'!K2<>"",'Revisor A'!K2,IF('Revisor A'!J2="","não preenchido",IF(LOWER(TRIM('Revisor A'!J2))=LOWER(TRIM(INDEX(Gabarito!$D:$D,MATCH($A2,Gabarito!$A:$A,0)))),"confere","diverge"))) | F2: =IF('Revisor A'!M2<>"",'Revisor A'!M2,IF('Revisor A'!L2="","não preenchido",IF(LOWER(TRIM('Revisor A'!L2))=LOWER(TRIM(INDEX(Gabarito!$E:$E,MATCH($A2,Gabarito!$A:$A,0)))),"confere","diverge"))) | G2: =IF('Revisor A'!O2<>"",'Revisor A'!O2,IF('Revisor A'!N2="","não preenchido",IF(LOWER(TRIM('Revisor A'!N2))=LOWER(TRIM(INDEX(Gabarito!$F:$F,MATCH($A2,Gabarito!$A:$A,0)))),"confere","diverge"))) | H2: =IF('Revisor A'!Q2<>"",'Revisor A'!Q2,IF('Revisor A'!P2="","não preenchido",IF(LOWER(TRIM('Revisor A'!P2))=LOWER(TRIM(INDEX(Gabarito!$G:$G,MATCH($A2,Gabarito!$A:$A,0)))),"confere","diverge"))) | I2: =IF('Revisor A'!S2<>"",'Revisor A'!S2,IF('Revisor A'!R2="","não preenchido",IF(LOWER(TRIM('Revisor A'!R2))=LOWER(TRIM(INDEX(Gabarito!$H:$H,MATCH($A2,Gabarito!$A:$A,0)))),"confere","diverge"))) | J2: =IF('Revisor A'!U2<>"",'Revisor A'!U2,IF('Revisor A'!T2="","não preenchido",IF(LOWER(TRIM('Revisor A'!T2))=LOWER(TRIM(INDEX(Gabarito!$I:$I,MATCH($A2,Gabarito!$A:$A,0)))),"confere","diverge"))) | K2: =IF('Revisor A'!W2<>"",'Revisor A'!W2,IF('Revisor A'!V2="","não preenchido",IF(LOWER(TRIM('Revisor A'!V2))=LOWER(TRIM(INDEX(Gabarito!$J:$J,MATCH($A2,Gabarito!$A:$A,0)))),"confere","diverge"))) | L2: =IF('Revisor A'!AB2="","não preenchido",'Revisor A'!AB2) | M2: =IF('Revisor A'!AC2="","não preenchido",'Revisor A'!AC2) | N2: =COUNTIF(C2:K2,"diverge") | O2: =IF(COUNTIF(C2:K2,"não preenchido")=9,"não preenchido",IF(N2>0,"diverge","confere"))
A3: ='Revisor A'!A3 | B3: =IFERROR(INDEX(Gabarito!$M:$M,MATCH($A3,Gabarito!$A:$A,0)),"") | C3: =IF('Revisor A'!G3<>"",'Revisor A'!G3,IF('Revisor A'!F3="","não preenchido",IF(ABS(N('Revisor A'!F3)-N(INDEX(Gabarito!$B:$B,MATCH($A3,Gabarito!$A:$A,0))))<=1,"confere","diverge"))) | D3: =IF('Revisor A'!I3<>"",'Revisor A'!I3,IF('Revisor A'!H3="","não preenchido",IF(ABS(N('Revisor A'!H3)-N(INDEX(Gabarito!$C:$C,MATCH($A3,Gabarito!$A:$A,0))))<=1,"confere","diverge"))) | E3: =IF('Revisor A'!K3<>"",'Revisor A'!K3,IF('Revisor A'!J3="","não preenchido",IF(LOWER(TRIM('Revisor A'!J3))=LOWER(TRIM(INDEX(Gabarito!$D:$D,MATCH($A3,Gabarito!$A:$A,0)))),"confere","diverge"))) | F3: =IF('Revisor A'!M3<>"",'Revisor A'!M3,IF('Revisor A'!L3="","não preenchido",IF(LOWER(TRIM('Revisor A'!L3))=LOWER(TRIM(INDEX(Gabarito!$E:$E,MATCH($A3,Gabarito!$A:$A,0)))),"confere","diverge"))) | G3: =IF('Revisor A'!O3<>"",'Revisor A'!O3,IF('Revisor A'!N3="","não preenchido",IF(LOWER(TRIM('Revisor A'!N3))=LOWER(TRIM(INDEX(Gabarito!$F:$F,MATCH($A3,Gabarito!$A:$A,0)))),"confere","diverge"))) | H3: =IF('Revisor A'!Q3<>"",'Revisor A'!Q3,IF('Revisor A'!P3="","não preenchido",IF(LOWER(TRIM('Revisor A'!P3))=LOWER(TRIM(INDEX(Gabarito!$G:$G,MATCH($A3,Gabarito!$A:$A,0)))),"confere","diverge"))) | I3: =IF('Revisor A'!S3<>"",'Revisor A'!S3,IF('Revisor A'!R3="","não preenchido",IF(LOWER(TRIM('Revisor A'!R3))=LOWER(TRIM(INDEX(Gabarito!$H:$H,MATCH($A3,Gabarito!$A:$A,0)))),"confere","diverge"))) | J3: =IF('Revisor A'!U3<>"",'Revisor A'!U3,IF('Revisor A'!T3="","não preenchido",IF(LOWER(TRIM('Revisor A'!T3))=LOWER(TRIM(INDEX(Gabarito!$I:$I,MATCH($A3,Gabarito!$A:$A,0)))),"confere","diverge"))) | K3: =IF('Revisor A'!W3<>"",'Revisor A'!W3,IF('Revisor A'!V3="","não preenchido",IF(LOWER(TRIM('Revisor A'!V3))=LOWER(TRIM(INDEX(Gabarito!$J:$J,MATCH($A3,Gabarito!$A:$A,0)))),"confere","diverge"))) | L3: =IF('Revisor A'!AB3="","não preenchido",'Revisor A'!AB3) | M3: =IF('Revisor A'!AC3="","não preenchido",'Revisor A'!AC3) | N3: =COUNTIF(C3:K3,"diverge") | O3: =IF(COUNTIF(C3:K3,"não preenchido")=9,"não preenchido",IF(N3>0,"diverge","confere"))
A4: ='Revisor A'!A4 | B4: =IFERROR(INDEX(Gabarito!$M:$M,MATCH($A4,Gabarito!$A:$A,0)),"") | C4: =IF('Revisor A'!G4<>"",'Revisor A'!G4,IF('Revisor A'!F4="","não preenchido",IF(ABS(N('Revisor A'!F4)-N(INDEX(Gabarito!$B:$B,MATCH($A4,Gabarito!$A:$A,0))))<=1,"confere","diverge"))) | D4: =IF('Revisor A'!I4<>"",'Revisor A'!I4,IF('Revisor A'!H4="","não preenchido",IF(ABS(N('Revisor A'!H4)-N(INDEX(Gabarito!$C:$C,MATCH($A4,Gabarito!$A:$A,0))))<=1,"confere","diverge"))) | E4: =IF('Revisor A'!K4<>"",'Revisor A'!K4,IF('Revisor A'!J4="","não preenchido",IF(LOWER(TRIM('Revisor A'!J4))=LOWER(TRIM(INDEX(Gabarito!$D:$D,MATCH($A4,Gabarito!$A:$A,0)))),"confere","diverge"))) | F4: =IF('Revisor A'!M4<>"",'Revisor A'!M4,IF('Revisor A'!L4="","não preenchido",IF(LOWER(TRIM('Revisor A'!L4))=LOWER(TRIM(INDEX(Gabarito!$E:$E,MATCH($A4,Gabarito!$A:$A,0)))),"confere","diverge"))) | G4: =IF('Revisor A'!O4<>"",'Revisor A'!O4,IF('Revisor A'!N4="","não preenchido",IF(LOWER(TRIM('Revisor A'!N4))=LOWER(TRIM(INDEX(Gabarito!$F:$F,MATCH($A4,Gabarito!$A:$A,0)))),"confere","diverge"))) | H4: =IF('Revisor A'!Q4<>"",'Revisor A'!Q4,IF('Revisor A'!P4="","não preenchido",IF(LOWER(TRIM('Revisor A'!P4))=LOWER(TRIM(INDEX(Gabarito!$G:$G,MATCH($A4,Gabarito!$A:$A,0)))),"confere","diverge"))) | I4: =IF('Revisor A'!S4<>"",'Revisor A'!S4,IF('Revisor A'!R4="","não preenchido",IF(LOWER(TRIM('Revisor A'!R4))=LOWER(TRIM(INDEX(Gabarito!$H:$H,MATCH($A4,Gabarito!$A:$A,0)))),"confere","diverge"))) | J4: =IF('Revisor A'!U4<>"",'Revisor A'!U4,IF('Revisor A'!T4="","não preenchido",IF(LOWER(TRIM('Revisor A'!T4))=LOWER(TRIM(INDEX(Gabarito!$I:$I,MATCH($A4,Gabarito!$A:$A,0)))),"confere","diverge"))) | K4: =IF('Revisor A'!W4<>"",'Revisor A'!W4,IF('Revisor A'!V4="","não preenchido",IF(LOWER(TRIM('Revisor A'!V4))=LOWER(TRIM(INDEX(Gabarito!$J:$J,MATCH($A4,Gabarito!$A:$A,0)))),"confere","diverge"))) | L4: =IF('Revisor A'!AB4="","não preenchido",'Revisor A'!AB4) | M4: =IF('Revisor A'!AC4="","não preenchido",'Revisor A'!AC4) | N4: =COUNTIF(C4:K4,"diverge") | O4: =IF(COUNTIF(C4:K4,"não preenchido")=9,"não preenchido",IF(N4>0,"diverge","confere"))
A5: ='Revisor A'!A5 | B5: =IFERROR(INDEX(Gabarito!$M:$M,MATCH($A5,Gabarito!$A:$A,0)),"") | C5: =IF('Revisor A'!G5<>"",'Revisor A'!G5,IF('Revisor A'!F5="","não preenchido",IF(ABS(N('Revisor A'!F5)-N(INDEX(Gabarito!$B:$B,MATCH($A5,Gabarito!$A:$A,0))))<=1,"confere","diverge"))) | D5: =IF('Revisor A'!I5<>"",'Revisor A'!I5,IF('Revisor A'!H5="","não preenchido",IF(ABS(N('Revisor A'!H5)-N(INDEX(Gabarito!$C:$C,MATCH($A5,Gabarito!$A:$A,0))))<=1,"confere","diverge"))) | E5: =IF('Revisor A'!K5<>"",'Revisor A'!K5,IF('Revisor A'!J5="","não preenchido",IF(LOWER(TRIM('Revisor A'!J5))=LOWER(TRIM(INDEX(Gabarito!$D:$D,MATCH($A5,Gabarito!$A:$A,0)))),"confere","diverge"))) | F5: =IF('Revisor A'!M5<>"",'Revisor A'!M5,IF('Revisor A'!L5="","não preenchido",IF(LOWER(TRIM('Revisor A'!L5))=LOWER(TRIM(INDEX(Gabarito!$E:$E,MATCH($A5,Gabarito!$A:$A,0)))),"confere","diverge"))) | G5: =IF('Revisor A'!O5<>"",'Revisor A'!O5,IF('Revisor A'!N5="","não preenchido",IF(LOWER(TRIM('Revisor A'!N5))=LOWER(TRIM(INDEX(Gabarito!$F:$F,MATCH($A5,Gabarito!$A:$A,0)))),"confere","diverge"))) | H5: =IF('Revisor A'!Q5<>"",'Revisor A'!Q5,IF('Revisor A'!P5="","não preenchido",IF(LOWER(TRIM('Revisor A'!P5))=LOWER(TRIM(INDEX(Gabarito!$G:$G,MATCH($A5,Gabarito!$A:$A,0)))),"confere","diverge"))) | I5: =IF('Revisor A'!S5<>"",'Revisor A'!S5,IF('Revisor A'!R5="","não preenchido",IF(LOWER(TRIM('Revisor A'!R5))=LOWER(TRIM(INDEX(Gabarito!$H:$H,MATCH($A5,Gabarito!$A:$A,0)))),"confere","diverge"))) | J5: =IF('Revisor A'!U5<>"",'Revisor A'!U5,IF('Revisor A'!T5="","não preenchido",IF(LOWER(TRIM('Revisor A'!T5))=LOWER(TRIM(INDEX(Gabarito!$I:$I,MATCH($A5,Gabarito!$A:$A,0)))),"confere","diverge"))) | K5: =IF('Revisor A'!W5<>"",'Revisor A'!W5,IF('Revisor A'!V5="","não preenchido",IF(LOWER(TRIM('Revisor A'!V5))=LOWER(TRIM(INDEX(Gabarito!$J:$J,MATCH($A5,Gabarito!$A:$A,0)))),"confere","diverge"))) | L5: =IF('Revisor A'!AB5="","não preenchido",'Revisor A'!AB5) | M5: =IF('Revisor A'!AC5="","não preenchido",'Revisor A'!AC5) | N5: =COUNTIF(C5:K5,"diverge") | O5: =IF(COUNTIF(C5:K5,"não preenchido")=9,"não preenchido",IF(N5>0,"diverge","confere"))
A6: ='Revisor A'!A6 | B6: =IFERROR(INDEX(Gabarito!$M:$M,MATCH($A6,Gabarito!$A:$A,0)),"") | C6: =IF('Revisor A'!G6<>"",'Revisor A'!G6,IF('Revisor A'!F6="","não preenchido",IF(ABS(N('Revisor A'!F6)-N(INDEX(Gabarito!$B:$B,MATCH($A6,Gabarito!$A:$A,0))))<=1,"confere","diverge"))) | D6: =IF('Revisor A'!I6<>"",'Revisor A'!I6,IF('Revisor A'!H6="","não preenchido",IF(ABS(N('Revisor A'!H6)-N(INDEX(Gabarito!$C:$C,MATCH($A6,Gabarito!$A:$A,0))))<=1,"confere","diverge"))) | E6: =IF('Revisor A'!K6<>"",'Revisor A'!K6,IF('Revisor A'!J6="","não preenchido",IF(LOWER(TRIM('Revisor A'!J6))=LOWER(TRIM(INDEX(Gabarito!$D:$D,MATCH($A6,Gabarito!$A:$A,0)))),"confere","diverge"))) | F6: =IF('Revisor A'!M6<>"",'Revisor A'!M6,IF('Revisor A'!L6="","não preenchido",IF(LOWER(TRIM('Revisor A'!L6))=LOWER(TRIM(INDEX(Gabarito!$E:$E,MATCH($A6,Gabarito!$A:$A,0)))),"confere","diverge"))) | G6: =IF('Revisor A'!O6<>"",'Revisor A'!O6,IF('Revisor A'!N6="","não preenchido",IF(LOWER(TRIM('Revisor A'!N6))=LOWER(TRIM(INDEX(Gabarito!$F:$F,MATCH($A6,Gabarito!$A:$A,0)))),"confere","diverge"))) | H6: =IF('Revisor A'!Q6<>"",'Revisor A'!Q6,IF('Revisor A'!P6="","não preenchido",IF(LOWER(TRIM('Revisor A'!P6))=LOWER(TRIM(INDEX(Gabarito!$G:$G,MATCH($A6,Gabarito!$A:$A,0)))),"confere","diverge"))) | I6: =IF('Revisor A'!S6<>"",'Revisor A'!S6,IF('Revisor A'!R6="","não preenchido",IF(LOWER(TRIM('Revisor A'!R6))=LOWER(TRIM(INDEX(Gabarito!$H:$H,MATCH($A6,Gabarito!$A:$A,0)))),"confere","diverge"))) | J6: =IF('Revisor A'!U6<>"",'Revisor A'!U6,IF('Revisor A'!T6="","não preenchido",IF(LOWER(TRIM('Revisor A'!T6))=LOWER(TRIM(INDEX(Gabarito!$I:$I,MATCH($A6,Gabarito!$A:$A,0)))),"confere","diverge"))) | K6: =IF('Revisor A'!W6<>"",'Revisor A'!W6,IF('Revisor A'!V6="","não preenchido",IF(LOWER(TRIM('Revisor A'!V6))=LOWER(TRIM(INDEX(Gabarito!$J:$J,MATCH($A6,Gabarito!$A:$A,0)))),"confere","diverge"))) | L6: =IF('Revisor A'!AB6="","não preenchido",'Revisor A'!AB6) | M6: =IF('Revisor A'!AC6="","não preenchido",'Revisor A'!AC6) | N6: =COUNTIF(C6:K6,"diverge") | O6: =IF(COUNTIF(C6:K6,"não preenchido")=9,"não preenchido",IF(N6>0,"diverge","confere"))
A7: ='Revisor A'!A7 | B7: =IFERROR(INDEX(Gabarito!$M:$M,MATCH($A7,Gabarito!$A:$A,0)),"") | C7: =IF('Revisor A'!G7<>"",'Revisor A'!G7,IF('Revisor A'!F7="","não preenchido",IF(ABS(N('Revisor A'!F7)-N(INDEX(Gabarito!$B:$B,MATCH($A7,Gabarito!$A:$A,0))))<=1,"confere","diverge"))) | D7: =IF('Revisor A'!I7<>"",'Revisor A'!I7,IF('Revisor A'!H7="","não preenchido",IF(ABS(N('Revisor A'!H7)-N(INDEX(Gabarito!$C:$C,MATCH($A7,Gabarito!$A:$A,0))))<=1,"confere","diverge"))) | E7: =IF('Revisor A'!K7<>"",'Revisor A'!K7,IF('Revisor A'!J7="","não preenchido",IF(LOWER(TRIM('Revisor A'!J7))=LOWER(TRIM(INDEX(Gabarito!$D:$D,MATCH($A7,Gabarito!$A:$A,0)))),"confere","diverge"))) | F7: =IF('Revisor A'!M7<>"",'Revisor A'!M7,IF('Revisor A'!L7="","não preenchido",IF(LOWER(TRIM('Revisor A'!L7))=LOWER(TRIM(INDEX(Gabarito!$E:$E,MATCH($A7,Gabarito!$A:$A,0)))),"confere","diverge"))) | G7: =IF('Revisor A'!O7<>"",'Revisor A'!O7,IF('Revisor A'!N7="","não preenchido",IF(LOWER(TRIM('Revisor A'!N7))=LOWER(TRIM(INDEX(Gabarito!$F:$F,MATCH($A7,Gabarito!$A:$A,0)))),"confere","diverge"))) | H7: =IF('Revisor A'!Q7<>"",'Revisor A'!Q7,IF('Revisor A'!P7="","não preenchido",IF(LOWER(TRIM('Revisor A'!P7))=LOWER(TRIM(INDEX(Gabarito!$G:$G,MATCH($A7,Gabarito!$A:$A,0)))),"confere","diverge"))) | I7: =IF('Revisor A'!S7<>"",'Revisor A'!S7,IF('Revisor A'!R7="","não preenchido",IF(LOWER(TRIM('Revisor A'!R7))=LOWER(TRIM(INDEX(Gabarito!$H:$H,MATCH($A7,Gabarito!$A:$A,0)))),"confere","diverge"))) | J7: =IF('Revisor A'!U7<>"",'Revisor A'!U7,IF('Revisor A'!T7="","não preenchido",IF(LOWER(TRIM('Revisor A'!T7))=LOWER(TRIM(INDEX(Gabarito!$I:$I,MATCH($A7,Gabarito!$A:$A,0)))),"confere","diverge"))) | K7: =IF('Revisor A'!W7<>"",'Revisor A'!W7,IF('Revisor A'!V7="","não preenchido",IF(LOWER(TRIM('Revisor A'!V7))=LOWER(TRIM(INDEX(Gabarito!$J:$J,MATCH($A7,Gabarito!$A:$A,0)))),"confere","diverge"))) | L7: =IF('Revisor A'!AB7="","não preenchido",'Revisor A'!AB7) | M7: =IF('Revisor A'!AC7="","não preenchido",'Revisor A'!AC7) | N7: =COUNTIF(C7:K7,"diverge") | O7: =IF(COUNTIF(C7:K7,"não preenchido")=9,"não preenchido",IF(N7>0,"diverge","confere"))
A8: ='Revisor A'!A8 | B8: =IFERROR(INDEX(Gabarito!$M:$M,MATCH($A8,Gabarito!$A:$A,0)),"") | C8: =IF('Revisor A'!G8<>"",'Revisor A'!G8,IF('Revisor A'!F8="","não preenchido",IF(ABS(N('Revisor A'!F8)-N(INDEX(Gabarito!$B:$B,MATCH($A8,Gabarito!$A:$A,0))))<=1,"confere","diverge"))) | D8: =IF('Revisor A'!I8<>"",'Revisor A'!I8,IF('Revisor A'!H8="","não preenchido",IF(ABS(N('Revisor A'!H8)-N(INDEX(Gabarito!$C:$C,MATCH($A8,Gabarito!$A:$A,0))))<=1,"confere","diverge"))) | E8: =IF('Revisor A'!K8<>"",'Revisor A'!K8,IF('Revisor A'!J8="","não preenchido",IF(LOWER(TRIM('Revisor A'!J8))=LOWER(TRIM(INDEX(Gabarito!$D:$D,MATCH($A8,Gabarito!$A:$A,0)))),"confere","diverge"))) | F8: =IF('Revisor A'!M8<>"",'Revisor A'!M8,IF('Revisor A'!L8="","não preenchido",IF(LOWER(TRIM('Revisor A'!L8))=LOWER(TRIM(INDEX(Gabarito!$E:$E,MATCH($A8,Gabarito!$A:$A,0)))),"confere","diverge"))) | G8: =IF('Revisor A'!O8<>"",'Revisor A'!O8,IF('Revisor A'!N8="","não preenchido",IF(LOWER(TRIM('Revisor A'!N8))=LOWER(TRIM(INDEX(Gabarito!$F:$F,MATCH($A8,Gabarito!$A:$A,0)))),"confere","diverge"))) | H8: =IF('Revisor A'!Q8<>"",'Revisor A'!Q8,IF('Revisor A'!P8="","não preenchido",IF(LOWER(TRIM('Revisor A'!P8))=LOWER(TRIM(INDEX(Gabarito!$G:$G,MATCH($A8,Gabarito!$A:$A,0)))),"confere","diverge"))) | I8: =IF('Revisor A'!S8<>"",'Revisor A'!S8,IF('Revisor A'!R8="","não preenchido",IF(LOWER(TRIM('Revisor A'!R8))=LOWER(TRIM(INDEX(Gabarito!$H:$H,MATCH($A8,Gabarito!$A:$A,0)))),"confere","diverge"))) | J8: =IF('Revisor A'!U8<>"",'Revisor A'!U8,IF('Revisor A'!T8="","não preenchido",IF(LOWER(TRIM('Revisor A'!T8))=LOWER(TRIM(INDEX(Gabarito!$I:$I,MATCH($A8,Gabarito!$A:$A,0)))),"confere","diverge"))) | K8: =IF('Revisor A'!W8<>"",'Revisor A'!W8,IF('Revisor A'!V8="","não preenchido",IF(LOWER(TRIM('Revisor A'!V8))=LOWER(TRIM(INDEX(Gabarito!$J:$J,MATCH($A8,Gabarito!$A:$A,0)))),"confere","diverge"))) | L8: =IF('Revisor A'!AB8="","não preenchido",'Revisor A'!AB8) | M8: =IF('Revisor A'!AC8="","não preenchido",'Revisor A'!AC8) | N8: =COUNTIF(C8:K8,"diverge") | O8: =IF(COUNTIF(C8:K8,"não preenchido")=9,"não preenchido",IF(N8>0,"diverge","confere"))
A9: ='Revisor A'!A9 | B9: =IFERROR(INDEX(Gabarito!$M:$M,MATCH($A9,Gabarito!$A:$A,0)),"") | C9: =IF('Revisor A'!G9<>"",'Revisor A'!G9,IF('Revisor A'!F9="","não preenchido",IF(ABS(N('Revisor A'!F9)-N(INDEX(Gabarito!$B:$B,MATCH($A9,Gabarito!$A:$A,0))))<=1,"confere","diverge"))) | D9: =IF('Revisor A'!I9<>"",'Revisor A'!I9,IF('Revisor A'!H9="","não preenchido",IF(ABS(N('Revisor A'!H9)-N(INDEX(Gabarito!$C:$C,MATCH($A9,Gabarito!$A:$A,0))))<=1,"confere","diverge"))) | E9: =IF('Revisor A'!K9<>"",'Revisor A'!K9,IF('Revisor A'!J9="","não preenchido",IF(LOWER(TRIM('Revisor A'!J9))=LOWER(TRIM(INDEX(Gabarito!$D:$D,MATCH($A9,Gabarito!$A:$A,0)))),"confere","diverge"))) | F9: =IF('Revisor A'!M9<>"",'Revisor A'!M9,IF('Revisor A'!L9="","não preenchido",IF(LOWER(TRIM('Revisor A'!L9))=LOWER(TRIM(INDEX(Gabarito!$E:$E,MATCH($A9,Gabarito!$A:$A,0)))),"confere","diverge"))) | G9: =IF('Revisor A'!O9<>"",'Revisor A'!O9,IF('Revisor A'!N9="","não preenchido",IF(LOWER(TRIM('Revisor A'!N9))=LOWER(TRIM(INDEX(Gabarito!$F:$F,MATCH($A9,Gabarito!$A:$A,0)))),"confere","diverge"))) | H9: =IF('Revisor A'!Q9<>"",'Revisor A'!Q9,IF('Revisor A'!P9="","não preenchido",IF(LOWER(TRIM('Revisor A'!P9))=LOWER(TRIM(INDEX(Gabarito!$G:$G,MATCH($A9,Gabarito!$A:$A,0)))),"confere","diverge"))) | I9: =IF('Revisor A'!S9<>"",'Revisor A'!S9,IF('Revisor A'!R9="","não preenchido",IF(LOWER(TRIM('Revisor A'!R9))=LOWER(TRIM(INDEX(Gabarito!$H:$H,MATCH($A9,Gabarito!$A:$A,0)))),"confere","diverge"))) | J9: =IF('Revisor A'!U9<>"",'Revisor A'!U9,IF('Revisor A'!T9="","não preenchido",IF(LOWER(TRIM('Revisor A'!T9))=LOWER(TRIM(INDEX(Gabarito!$I:$I,MATCH($A9,Gabarito!$A:$A,0)))),"confere","diverge"))) | K9: =IF('Revisor A'!W9<>"",'Revisor A'!W9,IF('Revisor A'!V9="","não preenchido",IF(LOWER(TRIM('Revisor A'!V9))=LOWER(TRIM(INDEX(Gabarito!$J:$J,MATCH($A9,Gabarito!$A:$A,0)))),"confere","diverge"))) | L9: =IF('Revisor A'!AB9="","não preenchido",'Revisor A'!AB9) | M9: =IF('Revisor A'!AC9="","não preenchido",'Revisor A'!AC9) | N9: =COUNTIF(C9:K9,"diverge") | O9: =IF(COUNTIF(C9:K9,"não preenchido")=9,"não preenchido",IF(N9>0,"diverge","confere"))
A10: ='Revisor A'!A10 | B10: =IFERROR(INDEX(Gabarito!$M:$M,MATCH($A10,Gabarito!$A:$A,0)),"") | C10: =IF('Revisor A'!G10<>"",'Revisor A'!G10,IF('Revisor A'!F10="","não preenchido",IF(ABS(N('Revisor A'!F10)-N(INDEX(Gabarito!$B:$B,MATCH($A10,Gabarito!$A:$A,0))))<=1,"confere","diverge"))) | D10: =IF('Revisor A'!I10<>"",'Revisor A'!I10,IF('Revisor A'!H10="","não preenchido",IF(ABS(N('Revisor A'!H10)-N(INDEX(Gabarito!$C:$C,MATCH($A10,Gabarito!$A:$A,0))))<=1,"confere","diverge"))) | E10: =IF('Revisor A'!K10<>"",'Revisor A'!K10,IF('Revisor A'!J10="","não preenchido",IF(LOWER(TRIM('Revisor A'!J10))=LOWER(TRIM(INDEX(Gabarito!$D:$D,MATCH($A10,Gabarito!$A:$A,0)))),"confere","diverge"))) | F10: =IF('Revisor A'!M10<>"",'Revisor A'!M10,IF('Revisor A'!L10="","não preenchido",IF(LOWER(TRIM('Revisor A'!L10))=LOWER(TRIM(INDEX(Gabarito!$E:$E,MATCH($A10,Gabarito!$A:$A,0)))),"confere","diverge"))) | G10: =IF('Revisor A'!O10<>"",'Revisor A'!O10,IF('Revisor A'!N10="","não preenchido",IF(LOWER(TRIM('Revisor A'!N10))=LOWER(TRIM(INDEX(Gabarito!$F:$F,MATCH($A10,Gabarito!$A:$A,0)))),"confere","diverge"))) | H10: =IF('Revisor A'!Q10<>"",'Revisor A'!Q10,IF('Revisor A'!P10="","não preenchido",IF(LOWER(TRIM('Revisor A'!P10))=LOWER(TRIM(INDEX(Gabarito!$G:$G,MATCH($A10,Gabarito!$A:$A,0)))),"confere","diverge"))) | I10: =IF('Revisor A'!S10<>"",'Revisor A'!S10,IF('Revisor A'!R10="","não preenchido",IF(LOWER(TRIM('Revisor A'!R10))=LOWER(TRIM(INDEX(Gabarito!$H:$H,MATCH($A10,Gabarito!$A:$A,0)))),"confere","diverge"))) | J10: =IF('Revisor A'!U10<>"",'Revisor A'!U10,IF('Revisor A'!T10="","não preenchido",IF(LOWER(TRIM('Revisor A'!T10))=LOWER(TRIM(INDEX(Gabarito!$I:$I,MATCH($A10,Gabarito!$A:$A,0)))),"confere","diverge"))) | K10: =IF('Revisor A'!W10<>"",'Revisor A'!W10,IF('Revisor A'!V10="","não preenchido",IF(LOWER(TRIM('Revisor A'!V10))=LOWER(TRIM(INDEX(Gabarito!$J:$J,MATCH($A10,Gabarito!$A:$A,0)))),"confere","diverge"))) | L10: =IF('Revisor A'!AB10="","não preenchido",'Revisor A'!AB10) | M10: =IF('Revisor A'!AC10="","não preenchido",'Revisor A'!AC10) | N10: =COUNTIF(C10:K10,"diverge") | O10: =IF(COUNTIF(C10:K10,"não preenchido")=9,"não preenchido",IF(N10>0,"diverge","confere"))
A11: ='Revisor A'!A11 | B11: =IFERROR(INDEX(Gabarito!$M:$M,MATCH($A11,Gabarito!$A:$A,0)),"") | C11: =IF('Revisor A'!G11<>"",'Revisor A'!G11,IF('Revisor A'!F11="","não preenchido",IF(ABS(N('Revisor A'!F11)-N(INDEX(Gabarito!$B:$B,MATCH($A11,Gabarito!$A:$A,0))))<=1,"confere","diverge"))) | D11: =IF('Revisor A'!I11<>"",'Revisor A'!I11,IF('Revisor A'!H11="","não preenchido",IF(ABS(N('Revisor A'!H11)-N(INDEX(Gabarito!$C:$C,MATCH($A11,Gabarito!$A:$A,0))))<=1,"confere","diverge"))) | E11: =IF('Revisor A'!K11<>"",'Revisor A'!K11,IF('Revisor A'!J11="","não preenchido",IF(LOWER(TRIM('Revisor A'!J11))=LOWER(TRIM(INDEX(Gabarito!$D:$D,MATCH($A11,Gabarito!$A:$A,0)))),"confere","diverge"))) | F11: =IF('Revisor A'!M11<>"",'Revisor A'!M11,IF('Revisor A'!L11="","não preenchido",IF(LOWER(TRIM('Revisor A'!L11))=LOWER(TRIM(INDEX(Gabarito!$E:$E,MATCH($A11,Gabarito!$A:$A,0)))),"confere","diverge"))) | G11: =IF('Revisor A'!O11<>"",'Revisor A'!O11,IF('Revisor A'!N11="","não preenchido",IF(LOWER(TRIM('Revisor A'!N11))=LOWER(TRIM(INDEX(Gabarito!$F:$F,MATCH($A11,Gabarito!$A:$A,0)))),"confere","diverge"))) | H11: =IF('Revisor A'!Q11<>"",'Revisor A'!Q11,IF('Revisor A'!P11="","não preenchido",IF(LOWER(TRIM('Revisor A'!P11))=LOWER(TRIM(INDEX(Gabarito!$G:$G,MATCH($A11,Gabarito!$A:$A,0)))),"confere","diverge"))) | I11: =IF('Revisor A'!S11<>"",'Revisor A'!S11,IF('Revisor A'!R11="","não preenchido",IF(LOWER(TRIM('Revisor A'!R11))=LOWER(TRIM(INDEX(Gabarito!$H:$H,MATCH($A11,Gabarito!$A:$A,0)))),"confere","diverge"))) | J11: =IF('Revisor A'!U11<>"",'Revisor A'!U11,IF('Revisor A'!T11="","não preenchido",IF(LOWER(TRIM('Revisor A'!T11))=LOWER(TRIM(INDEX(Gabarito!$I:$I,MATCH($A11,Gabarito!$A:$A,0)))),"confere","diverge"))) | K11: =IF('Revisor A'!W11<>"",'Revisor A'!W11,IF('Revisor A'!V11="","não preenchido",IF(LOWER(TRIM('Revisor A'!V11))=LOWER(TRIM(INDEX(Gabarito!$J:$J,MATCH($A11,Gabarito!$A:$A,0)))),"confere","diverge"))) | L11: =IF('Revisor A'!AB11="","não preenchido",'Revisor A'!AB11) | M11: =IF('Revisor A'!AC11="","não preenchido",'Revisor A'!AC11) | N11: =COUNTIF(C11:K11,"diverge") | O11: =IF(COUNTIF(C11:K11,"não preenchido")=9,"não preenchido",IF(N11>0,"diverge","confere"))
A12: ='Revisor A'!A12 | B12: =IFERROR(INDEX(Gabarito!$M:$M,MATCH($A12,Gabarito!$A:$A,0)),"") | C12: =IF('Revisor A'!G12<>"",'Revisor A'!G12,IF('Revisor A'!F12="","não preenchido",IF(ABS(N('Revisor A'!F12)-N(INDEX(Gabarito!$B:$B,MATCH($A12,Gabarito!$A:$A,0))))<=1,"confere","diverge"))) | D12: =IF('Revisor A'!I12<>"",'Revisor A'!I12,IF('Revisor A'!H12="","não preenchido",IF(ABS(N('Revisor A'!H12)-N(INDEX(Gabarito!$C:$C,MATCH($A12,Gabarito!$A:$A,0))))<=1,"confere","diverge"))) | E12: =IF('Revisor A'!K12<>"",'Revisor A'!K12,IF('Revisor A'!J12="","não preenchido",IF(LOWER(TRIM('Revisor A'!J12))=LOWER(TRIM(INDEX(Gabarito!$D:$D,MATCH($A12,Gabarito!$A:$A,0)))),"confere","diverge"))) | F12: =IF('Revisor A'!M12<>"",'Revisor A'!M12,IF('Revisor A'!L12="","não preenchido",IF(LOWER(TRIM('Revisor A'!L12))=LOWER(TRIM(INDEX(Gabarito!$E:$E,MATCH($A12,Gabarito!$A:$A,0)))),"confere","diverge"))) | G12: =IF('Revisor A'!O12<>"",'Revisor A'!O12,IF('Revisor A'!N12="","não preenchido",IF(LOWER(TRIM('Revisor A'!N12))=LOWER(TRIM(INDEX(Gabarito!$F:$F,MATCH($A12,Gabarito!$A:$A,0)))),"confere","diverge"))) | H12: =IF('Revisor A'!Q12<>"",'Revisor A'!Q12,IF('Revisor A'!P12="","não preenchido",IF(LOWER(TRIM('Revisor A'!P12))=LOWER(TRIM(INDEX(Gabarito!$G:$G,MATCH($A12,Gabarito!$A:$A,0)))),"confere","diverge"))) | I12: =IF('Revisor A'!S12<>"",'Revisor A'!S12,IF('Revisor A'!R12="","não preenchido",IF(LOWER(TRIM('Revisor A'!R12))=LOWER(TRIM(INDEX(Gabarito!$H:$H,MATCH($A12,Gabarito!$A:$A,0)))),"confere","diverge"))) | J12: =IF('Revisor A'!U12<>"",'Revisor A'!U12,IF('Revisor A'!T12="","não preenchido",IF(LOWER(TRIM('Revisor A'!T12))=LOWER(TRIM(INDEX(Gabarito!$I:$I,MATCH($A12,Gabarito!$A:$A,0)))),"confere","diverge"))) | K12: =IF('Revisor A'!W12<>"",'Revisor A'!W12,IF('Revisor A'!V12="","não preenchido",IF(LOWER(TRIM('Revisor A'!V12))=LOWER(TRIM(INDEX(Gabarito!$J:$J,MATCH($A12,Gabarito!$A:$A,0)))),"confere","diverge"))) | L12: =IF('Revisor A'!AB12="","não preenchido",'Revisor A'!AB12) | M12: =IF('Revisor A'!AC12="","não preenchido",'Revisor A'!AC12) | N12: =COUNTIF(C12:K12,"diverge") | O12: =IF(COUNTIF(C12:K12,"não preenchido")=9,"não preenchido",IF(N12>0,"diverge","confere"))
A13: ='Revisor A'!A13 | B13: =IFERROR(INDEX(Gabarito!$M:$M,MATCH($A13,Gabarito!$A:$A,0)),"") | C13: =IF('Revisor A'!G13<>"",'Revisor A'!G13,IF('Revisor A'!F13="","não preenchido",IF(ABS(N('Revisor A'!F13)-N(INDEX(Gabarito!$B:$B,MATCH($A13,Gabarito!$A:$A,0))))<=1,"confere","diverge"))) | D13: =IF('Revisor A'!I13<>"",'Revisor A'!I13,IF('Revisor A'!H13="","não preenchido",IF(ABS(N('Revisor A'!H13)-N(INDEX(Gabarito!$C:$C,MATCH($A13,Gabarito!$A:$A,0))))<=1,"confere","diverge"))) | E13: =IF('Revisor A'!K13<>"",'Revisor A'!K13,IF('Revisor A'!J13="","não preenchido",IF(LOWER(TRIM('Revisor A'!J13))=LOWER(TRIM(INDEX(Gabarito!$D:$D,MATCH($A13,Gabarito!$A:$A,0)))),"confere","diverge"))) | F13: =IF('Revisor A'!M13<>"",'Revisor A'!M13,IF('Revisor A'!L13="","não preenchido",IF(LOWER(TRIM('Revisor A'!L13))=LOWER(TRIM(INDEX(Gabarito!$E:$E,MATCH($A13,Gabarito!$A:$A,0)))),"confere","diverge"))) | G13: =IF('Revisor A'!O13<>"",'Revisor A'!O13,IF('Revisor A'!N13="","não preenchido",IF(LOWER(TRIM('Revisor A'!N13))=LOWER(TRIM(INDEX(Gabarito!$F:$F,MATCH($A13,Gabarito!$A:$A,0)))),"confere","diverge"))) | H13: =IF('Revisor A'!Q13<>"",'Revisor A'!Q13,IF('Revisor A'!P13="","não preenchido",IF(LOWER(TRIM('Revisor A'!P13))=LOWER(TRIM(INDEX(Gabarito!$G:$G,MATCH($A13,Gabarito!$A:$A,0)))),"confere","diverge"))) | I13: =IF('Revisor A'!S13<>"",'Revisor A'!S13,IF('Revisor A'!R13="","não preenchido",IF(LOWER(TRIM('Revisor A'!R13))=LOWER(TRIM(INDEX(Gabarito!$H:$H,MATCH($A13,Gabarito!$A:$A,0)))),"confere","diverge"))) | J13: =IF('Revisor A'!U13<>"",'Revisor A'!U13,IF('Revisor A'!T13="","não preenchido",IF(LOWER(TRIM('Revisor A'!T13))=LOWER(TRIM(INDEX(Gabarito!$I:$I,MATCH($A13,Gabarito!$A:$A,0)))),"confere","diverge"))) | K13: =IF('Revisor A'!W13<>"",'Revisor A'!W13,IF('Revisor A'!V13="","não preenchido",IF(LOWER(TRIM('Revisor A'!V13))=LOWER(TRIM(INDEX(Gabarito!$J:$J,MATCH($A13,Gabarito!$A:$A,0)))),"confere","diverge"))) | L13: =IF('Revisor A'!AB13="","não preenchido",'Revisor A'!AB13) | M13: =IF('Revisor A'!AC13="","não preenchido",'Revisor A'!AC13) | N13: =COUNTIF(C13:K13,"diverge") | O13: =IF(COUNTIF(C13:K13,"não preenchido")=9,"não preenchido",IF(N13>0,"diverge","confere"))
... A101: ='Revisor A'!A101 | B101: =IFERROR(INDEX(Gabarito!$M:$M,MATCH($A101,Gabarito!$A:$A,0)),"") | C101: =IF('Revisor A'!G101<>"",'Revisor A'!G101,IF('Revisor A'!F101="","não preenchido",IF(ABS(N('Revisor A'!F101)-N(INDEX(Gabarito!$B:$B,MATCH($A101,Gabarito!$A:$A,0))))<=1,"confere","diverge"))) | D101: =IF('Revisor A'!I101<>"",'Revisor A'!I101,IF('Revisor A'!H101="","não preenchido",IF(ABS(N('Revisor A'!H101)-N(INDEX(Gabarito!$C:$C,MATCH($A101,Gabarito!$A:$A,0))))<=1,"confere","diverge"))) | E101: =IF('Revisor A'!K101<>"",'Revisor A'!K101,IF('Revisor A'!J101="","não preenchido",IF(LOWER(TRIM('Revisor A'!J101))=LOWER(TRIM(INDEX(Gabarito!$D:$D,MATCH($A101,Gabarito!$A:$A,0)))),"confere","diverge"))) | F101: =IF('Revisor A'!M101<>"",'Revisor A'!M101,IF('Revisor A'!L101="","não preenchido",IF(LOWER(TRIM('Revisor A'!L101))=LOWER(TRIM(INDEX(Gabarito!$E:$E,MATCH($A101,Gabarito!$A:$A,0)))),"confere","diverge"))) | G101: =IF('Revisor A'!O101<>"",'Revisor A'!O101,IF('Revisor A'!N101="","não preenchido",IF(LOWER(TRIM('Revisor A'!N101))=LOWER(TRIM(INDEX(Gabarito!$F:$F,MATCH($A101,Gabarito!$A:$A,0)))),"confere","diverge"))) | H101: =IF('Revisor A'!Q101<>"",'Revisor A'!Q101,IF('Revisor A'!P101="","não preenchido",IF(LOWER(TRIM('Revisor A'!P101))=LOWER(TRIM(INDEX(Gabarito!$G:$G,MATCH($A101,Gabarito!$A:$A,0)))),"confere","diverge"))) | I101: =IF('Revisor A'!S101<>"",'Revisor A'!S101,IF('Revisor A'!R101="","não preenchido",IF(LOWER(TRIM('Revisor A'!R101))=LOWER(TRIM(INDEX(Gabarito!$H:$H,MATCH($A101,Gabarito!$A:$A,0)))),"confere","diverge"))) | J101: =IF('Revisor A'!U101<>"",'Revisor A'!U101,IF('Revisor A'!T101="","não preenchido",IF(LOWER(TRIM('Revisor A'!T101))=LOWER(TRIM(INDEX(Gabarito!$I:$I,MATCH($A101,Gabarito!$A:$A,0)))),"confere","diverge"))) | K101: =IF('Revisor A'!W101<>"",'Revisor A'!W101,IF('Revisor A'!V101="","não preenchido",IF(LOWER(TRIM('Revisor A'!V101))=LOWER(TRIM(INDEX(Gabarito!$J:$J,MATCH($A101,Gabarito!$A:$A,0)))),"confere","diverge"))) | L101: =IF('Revisor A'!AB101="","não preenchido",'Revisor A'!AB101) | M101: =IF('Revisor A'!AC101="","não preenchido",'Revisor A'!AC101) | N101: =COUNTIF(C101:K101,"diverge") | O101: =IF(COUNTIF(C101:K101,"não preenchido")=9,"não preenchido",IF(N101>0,"diverge","confere"))

Sheet Apuração B
A1: id | B1: estrato | C1: pena_min | D1: pena_max | E1: tipo_pena | F1: hediondo | G1: violencia | H1: grave_ameaca | I1: elemento | J1: tentativa | K1: acao | L1: nome | M1: vigência | N1: divergências S1 | O1: saída do registro | P1: A: pena_min | Q1: A: pena_max | R1: A: tipo_pena | S1: A: hediondo | T1: A: violencia | U1: A: grave_ameaca | V1: A: elemento | W1: A: tentativa | X1: A: acao
A2: ='Revisor B'!A2 | B2: =IFERROR(INDEX(Gabarito!$M:$M,MATCH($A2,Gabarito!$A:$A,0)),"") | C2: =IF('Revisor B'!G2<>"",'Revisor B'!G2,IF('Revisor B'!F2="","não preenchido",IF(ABS(N('Revisor B'!F2)-N(INDEX(Gabarito!$B:$B,MATCH($A2,Gabarito!$A:$A,0))))<=1,"confere","diverge"))) | D2: =IF('Revisor B'!I2<>"",'Revisor B'!I2,IF('Revisor B'!H2="","não preenchido",IF(ABS(N('Revisor B'!H2)-N(INDEX(Gabarito!$C:$C,MATCH($A2,Gabarito!$A:$A,0))))<=1,"confere","diverge"))) | E2: =IF('Revisor B'!K2<>"",'Revisor B'!K2,IF('Revisor B'!J2="","não preenchido",IF(LOWER(TRIM('Revisor B'!J2))=LOWER(TRIM(INDEX(Gabarito!$D:$D,MATCH($A2,Gabarito!$A:$A,0)))),"confere","diverge"))) | F2: =IF('Revisor B'!M2<>"",'Revisor B'!M2,IF('Revisor B'!L2="","não preenchido",IF(LOWER(TRIM('Revisor B'!L2))=LOWER(TRIM(INDEX(Gabarito!$E:$E,MATCH($A2,Gabarito!$A:$A,0)))),"confere","diverge"))) | G2: =IF('Revisor B'!O2<>"",'Revisor B'!O2,IF('Revisor B'!N2="","não preenchido",IF(LOWER(TRIM('Revisor B'!N2))=LOWER(TRIM(INDEX(Gabarito!$F:$F,MATCH($A2,Gabarito!$A:$A,0)))),"confere","diverge"))) | H2: =IF('Revisor B'!Q2<>"",'Revisor B'!Q2,IF('Revisor B'!P2="","não preenchido",IF(LOWER(TRIM('Revisor B'!P2))=LOWER(TRIM(INDEX(Gabarito!$G:$G,MATCH($A2,Gabarito!$A:$A,0)))),"confere","diverge"))) | I2: =IF('Revisor B'!S2<>"",'Revisor B'!S2,IF('Revisor B'!R2="","não preenchido",IF(LOWER(TRIM('Revisor B'!R2))=LOWER(TRIM(INDEX(Gabarito!$H:$H,MATCH($A2,Gabarito!$A:$A,0)))),"confere","diverge"))) | J2: =IF('Revisor B'!U2<>"",'Revisor B'!U2,IF('Revisor B'!T2="","não preenchido",IF(LOWER(TRIM('Revisor B'!T2))=LOWER(TRIM(INDEX(Gabarito!$I:$I,MATCH($A2,Gabarito!$A:$A,0)))),"confere","diverge"))) | K2: =IF('Revisor B'!W2<>"",'Revisor B'!W2,IF('Revisor B'!V2="","não preenchido",IF(LOWER(TRIM('Revisor B'!V2))=LOWER(TRIM(INDEX(Gabarito!$J:$J,MATCH($A2,Gabarito!$A:$A,0)))),"confere","diverge"))) | L2: =IF('Revisor B'!AB2="","não preenchido",'Revisor B'!AB2) | M2: =IF('Revisor B'!AC2="","não preenchido",'Revisor B'!AC2) | N2: =COUNTIF(C2:K2,"diverge") | O2: =IF(COUNTIF(C2:K2,"não preenchido")=9,"não preenchido",IF(N2>0,"diverge","confere")) | P2: =IFERROR(INDEX('Apuração A'!$C$2:$C$101,MATCH($A2,'Apuração A'!$A$2:$A$101,0)),"") | Q2: =IFERROR(INDEX('Apuração A'!$D$2:$D$101,MATCH($A2,'Apuração A'!$A$2:$A$101,0)),"") | R2: =IFERROR(INDEX('Apuração A'!$E$2:$E$101,MATCH($A2,'Apuração A'!$A$2:$A$101,0)),"") | S2: =IFERROR(INDEX('Apuração A'!$F$2:$F$101,MATCH($A2,'Apuração A'!$A$2:$A$101,0)),"") | T2: =IFERROR(INDEX('Apuração A'!$G$2:$G$101,MATCH($A2,'Apuração A'!$A$2:$A$101,0)),"") | U2: =IFERROR(INDEX('Apuração A'!$H$2:$H$101,MATCH($A2,'Apuração A'!$A$2:$A$101,0)),"") | V2: =IFERROR(INDEX('Apuração A'!$I$2:$I$101,MATCH($A2,'Apuração A'!$A$2:$A$101,0)),"") | W2: =IFERROR(INDEX('Apuração A'!$J$2:$J$101,MATCH($A2,'Apuração A'!$A$2:$A$101,0)),"") | X2: =IFERROR(INDEX('Apuração A'!$K$2:$K$101,MATCH($A2,'Apuração A'!$A$2:$A$101,0)),"")
A3: ='Revisor B'!A3 | B3: =IFERROR(INDEX(Gabarito!$M:$M,MATCH($A3,Gabarito!$A:$A,0)),"") | C3: =IF('Revisor B'!G3<>"",'Revisor B'!G3,IF('Revisor B'!F3="","não preenchido",IF(ABS(N('Revisor B'!F3)-N(INDEX(Gabarito!$B:$B,MATCH($A3,Gabarito!$A:$A,0))))<=1,"confere","diverge"))) | D3: =IF('Revisor B'!I3<>"",'Revisor B'!I3,IF('Revisor B'!H3="","não preenchido",IF(ABS(N('Revisor B'!H3)-N(INDEX(Gabarito!$C:$C,MATCH($A3,Gabarito!$A:$A,0))))<=1,"confere","diverge"))) | E3: =IF('Revisor B'!K3<>"",'Revisor B'!K3,IF('Revisor B'!J3="","não preenchido",IF(LOWER(TRIM('Revisor B'!J3))=LOWER(TRIM(INDEX(Gabarito!$D:$D,MATCH($A3,Gabarito!$A:$A,0)))),"confere","diverge"))) | F3: =IF('Revisor B'!M3<>"",'Revisor B'!M3,IF('Revisor B'!L3="","não preenchido",IF(LOWER(TRIM('Revisor B'!L3))=LOWER(TRIM(INDEX(Gabarito!$E:$E,MATCH($A3,Gabarito!$A:$A,0)))),"confere","diverge"))) | G3: =IF('Revisor B'!O3<>"",'Revisor B'!O3,IF('Revisor B'!N3="","não preenchido",IF(LOWER(TRIM('Revisor B'!N3))=LOWER(TRIM(INDEX(Gabarito!$F:$F,MATCH($A3,Gabarito!$A:$A,0)))),"confere","diverge"))) | H3: =IF('Revisor B'!Q3<>"",'Revisor B'!Q3,IF('Revisor B'!P3="","não preenchido",IF(LOWER(TRIM('Revisor B'!P3))=LOWER(TRIM(INDEX(Gabarito!$G:$G,MATCH($A3,Gabarito!$A:$A,0)))),"confere","diverge"))) | I3: =IF('Revisor B'!S3<>"",'Revisor B'!S3,IF('Revisor B'!R3="","não preenchido",IF(LOWER(TRIM('Revisor B'!R3))=LOWER(TRIM(INDEX(Gabarito!$H:$H,MATCH($A3,Gabarito!$A:$A,0)))),"confere","diverge"))) | J3: =IF('Revisor B'!U3<>"",'Revisor B'!U3,IF('Revisor B'!T3="","não preenchido",IF(LOWER(TRIM('Revisor B'!T3))=LOWER(TRIM(INDEX(Gabarito!$I:$I,MATCH($A3,Gabarito!$A:$A,0)))),"confere","diverge"))) | K3: =IF('Revisor B'!W3<>"",'Revisor B'!W3,IF('Revisor B'!V3="","não preenchido",IF(LOWER(TRIM('Revisor B'!V3))=LOWER(TRIM(INDEX(Gabarito!$J:$J,MATCH($A3,Gabarito!$A:$A,0)))),"confere","diverge"))) | L3: =IF('Revisor B'!AB3="","não preenchido",'Revisor B'!AB3) | M3: =IF('Revisor B'!AC3="","não preenchido",'Revisor B'!AC3) | N3: =COUNTIF(C3:K3,"diverge") | O3: =IF(COUNTIF(C3:K3,"não preenchido")=9,"não preenchido",IF(N3>0,"diverge","confere")) | P3: =IFERROR(INDEX('Apuração A'!$C$2:$C$101,MATCH($A3,'Apuração A'!$A$2:$A$101,0)),"") | Q3: =IFERROR(INDEX('Apuração A'!$D$2:$D$101,MATCH($A3,'Apuração A'!$A$2:$A$101,0)),"") | R3: =IFERROR(INDEX('Apuração A'!$E$2:$E$101,MATCH($A3,'Apuração A'!$A$2:$A$101,0)),"") | S3: =IFERROR(INDEX('Apuração A'!$F$2:$F$101,MATCH($A3,'Apuração A'!$A$2:$A$101,0)),"") | T3: =IFERROR(INDEX('Apuração A'!$G$2:$G$101,MATCH($A3,'Apuração A'!$A$2:$A$101,0)),"") | U3: =IFERROR(INDEX('Apuração A'!$H$2:$H$101,MATCH($A3,'Apuração A'!$A$2:$A$101,0)),"") | V3: =IFERROR(INDEX('Apuração A'!$I$2:$I$101,MATCH($A3,'Apuração A'!$A$2:$A$101,0)),"") | W3: =IFERROR(INDEX('Apuração A'!$J$2:$J$101,MATCH($A3,'Apuração A'!$A$2:$A$101,0)),"") | X3: =IFERROR(INDEX('Apuração A'!$K$2:$K$101,MATCH($A3,'Apuração A'!$A$2:$A$101,0)),"")
A4: ='Revisor B'!A4 | B4: =IFERROR(INDEX(Gabarito!$M:$M,MATCH($A4,Gabarito!$A:$A,0)),"") | C4: =IF('Revisor B'!G4<>"",'Revisor B'!G4,IF('Revisor B'!F4="","não preenchido",IF(ABS(N('Revisor B'!F4)-N(INDEX(Gabarito!$B:$B,MATCH($A4,Gabarito!$A:$A,0))))<=1,"confere","diverge"))) | D4: =IF('Revisor B'!I4<>"",'Revisor B'!I4,IF('Revisor B'!H4="","não preenchido",IF(ABS(N('Revisor B'!H4)-N(INDEX(Gabarito!$C:$C,MATCH($A4,Gabarito!$A:$A,0))))<=1,"confere","diverge"))) | E4: =IF('Revisor B'!K4<>"",'Revisor B'!K4,IF('Revisor B'!J4="","não preenchido",IF(LOWER(TRIM('Revisor B'!J4))=LOWER(TRIM(INDEX(Gabarito!$D:$D,MATCH($A4,Gabarito!$A:$A,0)))),"confere","diverge"))) | F4: =IF('Revisor B'!M4<>"",'Revisor B'!M4,IF('Revisor B'!L4="","não preenchido",IF(LOWER(TRIM('Revisor B'!L4))=LOWER(TRIM(INDEX(Gabarito!$E:$E,MATCH($A4,Gabarito!$A:$A,0)))),"confere","diverge"))) | G4: =IF('Revisor B'!O4<>"",'Revisor B'!O4,IF('Revisor B'!N4="","não preenchido",IF(LOWER(TRIM('Revisor B'!N4))=LOWER(TRIM(INDEX(Gabarito!$F:$F,MATCH($A4,Gabarito!$A:$A,0)))),"confere","diverge"))) | H4: =IF('Revisor B'!Q4<>"",'Revisor B'!Q4,IF('Revisor B'!P4="","não preenchido",IF(LOWER(TRIM('Revisor B'!P4))=LOWER(TRIM(INDEX(Gabarito!$G:$G,MATCH($A4,Gabarito!$A:$A,0)))),"confere","diverge"))) | I4: =IF('Revisor B'!S4<>"",'Revisor B'!S4,IF('Revisor B'!R4="","não preenchido",IF(LOWER(TRIM('Revisor B'!R4))=LOWER(TRIM(INDEX(Gabarito!$H:$H,MATCH($A4,Gabarito!$A:$A,0)))),"confere","diverge"))) | J4: =IF('Revisor B'!U4<>"",'Revisor B'!U4,IF('Revisor B'!T4="","não preenchido",IF(LOWER(TRIM('Revisor B'!T4))=LOWER(TRIM(INDEX(Gabarito!$I:$I,MATCH($A4,Gabarito!$A:$A,0)))),"confere","diverge"))) | K4: =IF('Revisor B'!W4<>"",'Revisor B'!W4,IF('Revisor B'!V4="","não preenchido",IF(LOWER(TRIM('Revisor B'!V4))=LOWER(TRIM(INDEX(Gabarito!$J:$J,MATCH($A4,Gabarito!$A:$A,0)))),"confere","diverge"))) | L4: =IF('Revisor B'!AB4="","não preenchido",'Revisor B'!AB4) | M4: =IF('Revisor B'!AC4="","não preenchido",'Revisor B'!AC4) | N4: =COUNTIF(C4:K4,"diverge") | O4: =IF(COUNTIF(C4:K4,"não preenchido")=9,"não preenchido",IF(N4>0,"diverge","confere")) | P4: =IFERROR(INDEX('Apuração A'!$C$2:$C$101,MATCH($A4,'Apuração A'!$A$2:$A$101,0)),"") | Q4: =IFERROR(INDEX('Apuração A'!$D$2:$D$101,MATCH($A4,'Apuração A'!$A$2:$A$101,0)),"") | R4: =IFERROR(INDEX('Apuração A'!$E$2:$E$101,MATCH($A4,'Apuração A'!$A$2:$A$101,0)),"") | S4: =IFERROR(INDEX('Apuração A'!$F$2:$F$101,MATCH($A4,'Apuração A'!$A$2:$A$101,0)),"") | T4: =IFERROR(INDEX('Apuração A'!$G$2:$G$101,MATCH($A4,'Apuração A'!$A$2:$A$101,0)),"") | U4: =IFERROR(INDEX('Apuração A'!$H$2:$H$101,MATCH($A4,'Apuração A'!$A$2:$A$101,0)),"") | V4: =IFERROR(INDEX('Apuração A'!$I$2:$I$101,MATCH($A4,'Apuração A'!$A$2:$A$101,0)),"") | W4: =IFERROR(INDEX('Apuração A'!$J$2:$J$101,MATCH($A4,'Apuração A'!$A$2:$A$101,0)),"") | X4: =IFERROR(INDEX('Apuração A'!$K$2:$K$101,MATCH($A4,'Apuração A'!$A$2:$A$101,0)),"")
A5: ='Revisor B'!A5 | B5: =IFERROR(INDEX(Gabarito!$M:$M,MATCH($A5,Gabarito!$A:$A,0)),"") | C5: =IF('Revisor B'!G5<>"",'Revisor B'!G5,IF('Revisor B'!F5="","não preenchido",IF(ABS(N('Revisor B'!F5)-N(INDEX(Gabarito!$B:$B,MATCH($A5,Gabarito!$A:$A,0))))<=1,"confere","diverge"))) | D5: =IF('Revisor B'!I5<>"",'Revisor B'!I5,IF('Revisor B'!H5="","não preenchido",IF(ABS(N('Revisor B'!H5)-N(INDEX(Gabarito!$C:$C,MATCH($A5,Gabarito!$A:$A,0))))<=1,"confere","diverge"))) | E5: =IF('Revisor B'!K5<>"",'Revisor B'!K5,IF('Revisor B'!J5="","não preenchido",IF(LOWER(TRIM('Revisor B'!J5))=LOWER(TRIM(INDEX(Gabarito!$D:$D,MATCH($A5,Gabarito!$A:$A,0)))),"confere","diverge"))) | F5: =IF('Revisor B'!M5<>"",'Revisor B'!M5,IF('Revisor B'!L5="","não preenchido",IF(LOWER(TRIM('Revisor B'!L5))=LOWER(TRIM(INDEX(Gabarito!$E:$E,MATCH($A5,Gabarito!$A:$A,0)))),"confere","diverge"))) | G5: =IF('Revisor B'!O5<>"",'Revisor B'!O5,IF('Revisor B'!N5="","não preenchido",IF(LOWER(TRIM('Revisor B'!N5))=LOWER(TRIM(INDEX(Gabarito!$F:$F,MATCH($A5,Gabarito!$A:$A,0)))),"confere","diverge"))) | H5: =IF('Revisor B'!Q5<>"",'Revisor B'!Q5,IF('Revisor B'!P5="","não preenchido",IF(LOWER(TRIM('Revisor B'!P5))=LOWER(TRIM(INDEX(Gabarito!$G:$G,MATCH($A5,Gabarito!$A:$A,0)))),"confere","diverge"))) | I5: =IF('Revisor B'!S5<>"",'Revisor B'!S5,IF('Revisor B'!R5="","não preenchido",IF(LOWER(TRIM('Revisor B'!R5))=LOWER(TRIM(INDEX(Gabarito!$H:$H,MATCH($A5,Gabarito!$A:$A,0)))),"confere","diverge"))) | J5: =IF('Revisor B'!U5<>"",'Revisor B'!U5,IF('Revisor B'!T5="","não preenchido",IF(LOWER(TRIM('Revisor B'!T5))=LOWER(TRIM(INDEX(Gabarito!$I:$I,MATCH($A5,Gabarito!$A:$A,0)))),"confere","diverge"))) | K5: =IF('Revisor B'!W5<>"",'Revisor B'!W5,IF('Revisor B'!V5="","não preenchido",IF(LOWER(TRIM('Revisor B'!V5))=LOWER(TRIM(INDEX(Gabarito!$J:$J,MATCH($A5,Gabarito!$A:$A,0)))),"confere","diverge"))) | L5: =IF('Revisor B'!AB5="","não preenchido",'Revisor B'!AB5) | M5: =IF('Revisor B'!AC5="","não preenchido",'Revisor B'!AC5) | N5: =COUNTIF(C5:K5,"diverge") | O5: =IF(COUNTIF(C5:K5,"não preenchido")=9,"não preenchido",IF(N5>0,"diverge","confere")) | P5: =IFERROR(INDEX('Apuração A'!$C$2:$C$101,MATCH($A5,'Apuração A'!$A$2:$A$101,0)),"") | Q5: =IFERROR(INDEX('Apuração A'!$D$2:$D$101,MATCH($A5,'Apuração A'!$A$2:$A$101,0)),"") | R5: =IFERROR(INDEX('Apuração A'!$E$2:$E$101,MATCH($A5,'Apuração A'!$A$2:$A$101,0)),"") | S5: =IFERROR(INDEX('Apuração A'!$F$2:$F$101,MATCH($A5,'Apuração A'!$A$2:$A$101,0)),"") | T5: =IFERROR(INDEX('Apuração A'!$G$2:$G$101,MATCH($A5,'Apuração A'!$A$2:$A$101,0)),"") | U5: =IFERROR(INDEX('Apuração A'!$H$2:$H$101,MATCH($A5,'Apuração A'!$A$2:$A$101,0)),"") | V5: =IFERROR(INDEX('Apuração A'!$I$2:$I$101,MATCH($A5,'Apuração A'!$A$2:$A$101,0)),"") | W5: =IFERROR(INDEX('Apuração A'!$J$2:$J$101,MATCH($A5,'Apuração A'!$A$2:$A$101,0)),"") | X5: =IFERROR(INDEX('Apuração A'!$K$2:$K$101,MATCH($A5,'Apuração A'!$A$2:$A$101,0)),"")
A6: ='Revisor B'!A6 | B6: =IFERROR(INDEX(Gabarito!$M:$M,MATCH($A6,Gabarito!$A:$A,0)),"") | C6: =IF('Revisor B'!G6<>"",'Revisor B'!G6,IF('Revisor B'!F6="","não preenchido",IF(ABS(N('Revisor B'!F6)-N(INDEX(Gabarito!$B:$B,MATCH($A6,Gabarito!$A:$A,0))))<=1,"confere","diverge"))) | D6: =IF('Revisor B'!I6<>"",'Revisor B'!I6,IF('Revisor B'!H6="","não preenchido",IF(ABS(N('Revisor B'!H6)-N(INDEX(Gabarito!$C:$C,MATCH($A6,Gabarito!$A:$A,0))))<=1,"confere","diverge"))) | E6: =IF('Revisor B'!K6<>"",'Revisor B'!K6,IF('Revisor B'!J6="","não preenchido",IF(LOWER(TRIM('Revisor B'!J6))=LOWER(TRIM(INDEX(Gabarito!$D:$D,MATCH($A6,Gabarito!$A:$A,0)))),"confere","diverge"))) | F6: =IF('Revisor B'!M6<>"",'Revisor B'!M6,IF('Revisor B'!L6="","não preenchido",IF(LOWER(TRIM('Revisor B'!L6))=LOWER(TRIM(INDEX(Gabarito!$E:$E,MATCH($A6,Gabarito!$A:$A,0)))),"confere","diverge"))) | G6: =IF('Revisor B'!O6<>"",'Revisor B'!O6,IF('Revisor B'!N6="","não preenchido",IF(LOWER(TRIM('Revisor B'!N6))=LOWER(TRIM(INDEX(Gabarito!$F:$F,MATCH($A6,Gabarito!$A:$A,0)))),"confere","diverge"))) | H6: =IF('Revisor B'!Q6<>"",'Revisor B'!Q6,IF('Revisor B'!P6="","não preenchido",IF(LOWER(TRIM('Revisor B'!P6))=LOWER(TRIM(INDEX(Gabarito!$G:$G,MATCH($A6,Gabarito!$A:$A,0)))),"confere","diverge"))) | I6: =IF('Revisor B'!S6<>"",'Revisor B'!S6,IF('Revisor B'!R6="","não preenchido",IF(LOWER(TRIM('Revisor B'!R6))=LOWER(TRIM(INDEX(Gabarito!$H:$H,MATCH($A6,Gabarito!$A:$A,0)))),"confere","diverge"))) | J6: =IF('Revisor B'!U6<>"",'Revisor B'!U6,IF('Revisor B'!T6="","não preenchido",IF(LOWER(TRIM('Revisor B'!T6))=LOWER(TRIM(INDEX(Gabarito!$I:$I,MATCH($A6,Gabarito!$A:$A,0)))),"confere","diverge"))) | K6: =IF('Revisor B'!W6<>"",'Revisor B'!W6,IF('Revisor B'!V6="","não preenchido",IF(LOWER(TRIM('Revisor B'!V6))=LOWER(TRIM(INDEX(Gabarito!$J:$J,MATCH($A6,Gabarito!$A:$A,0)))),"confere","diverge"))) | L6: =IF('Revisor B'!AB6="","não preenchido",'Revisor B'!AB6) | M6: =IF('Revisor B'!AC6="","não preenchido",'Revisor B'!AC6) | N6: =COUNTIF(C6:K6,"diverge") | O6: =IF(COUNTIF(C6:K6,"não preenchido")=9,"não preenchido",IF(N6>0,"diverge","confere")) | P6: =IFERROR(INDEX('Apuração A'!$C$2:$C$101,MATCH($A6,'Apuração A'!$A$2:$A$101,0)),"") | Q6: =IFERROR(INDEX('Apuração A'!$D$2:$D$101,MATCH($A6,'Apuração A'!$A$2:$A$101,0)),"") | R6: =IFERROR(INDEX('Apuração A'!$E$2:$E$101,MATCH($A6,'Apuração A'!$A$2:$A$101,0)),"") | S6: =IFERROR(INDEX('Apuração A'!$F$2:$F$101,MATCH($A6,'Apuração A'!$A$2:$A$101,0)),"") | T6: =IFERROR(INDEX('Apuração A'!$G$2:$G$101,MATCH($A6,'Apuração A'!$A$2:$A$101,0)),"") | U6: =IFERROR(INDEX('Apuração A'!$H$2:$H$101,MATCH($A6,'Apuração A'!$A$2:$A$101,0)),"") | V6: =IFERROR(INDEX('Apuração A'!$I$2:$I$101,MATCH($A6,'Apuração A'!$A$2:$A$101,0)),"") | W6: =IFERROR(INDEX('Apuração A'!$J$2:$J$101,MATCH($A6,'Apuração A'!$A$2:$A$101,0)),"") | X6: =IFERROR(INDEX('Apuração A'!$K$2:$K$101,MATCH($A6,'Apuração A'!$A$2:$A$101,0)),"")
A7: ='Revisor B'!A7 | B7: =IFERROR(INDEX(Gabarito!$M:$M,MATCH($A7,Gabarito!$A:$A,0)),"") | C7: =IF('Revisor B'!G7<>"",'Revisor B'!G7,IF('Revisor B'!F7="","não preenchido",IF(ABS(N('Revisor B'!F7)-N(INDEX(Gabarito!$B:$B,MATCH($A7,Gabarito!$A:$A,0))))<=1,"confere","diverge"))) | D7: =IF('Revisor B'!I7<>"",'Revisor B'!I7,IF('Revisor B'!H7="","não preenchido",IF(ABS(N('Revisor B'!H7)-N(INDEX(Gabarito!$C:$C,MATCH($A7,Gabarito!$A:$A,0))))<=1,"confere","diverge"))) | E7: =IF('Revisor B'!K7<>"",'Revisor B'!K7,IF('Revisor B'!J7="","não preenchido",IF(LOWER(TRIM('Revisor B'!J7))=LOWER(TRIM(INDEX(Gabarito!$D:$D,MATCH($A7,Gabarito!$A:$A,0)))),"confere","diverge"))) | F7: =IF('Revisor B'!M7<>"",'Revisor B'!M7,IF('Revisor B'!L7="","não preenchido",IF(LOWER(TRIM('Revisor B'!L7))=LOWER(TRIM(INDEX(Gabarito!$E:$E,MATCH($A7,Gabarito!$A:$A,0)))),"confere","diverge"))) | G7: =IF('Revisor B'!O7<>"",'Revisor B'!O7,IF('Revisor B'!N7="","não preenchido",IF(LOWER(TRIM('Revisor B'!N7))=LOWER(TRIM(INDEX(Gabarito!$F:$F,MATCH($A7,Gabarito!$A:$A,0)))),"confere","diverge"))) | H7: =IF('Revisor B'!Q7<>"",'Revisor B'!Q7,IF('Revisor B'!P7="","não preenchido",IF(LOWER(TRIM('Revisor B'!P7))=LOWER(TRIM(INDEX(Gabarito!$G:$G,MATCH($A7,Gabarito!$A:$A,0)))),"confere","diverge"))) | I7: =IF('Revisor B'!S7<>"",'Revisor B'!S7,IF('Revisor B'!R7="","não preenchido",IF(LOWER(TRIM('Revisor B'!R7))=LOWER(TRIM(INDEX(Gabarito!$H:$H,MATCH($A7,Gabarito!$A:$A,0)))),"confere","diverge"))) | J7: =IF('Revisor B'!U7<>"",'Revisor B'!U7,IF('Revisor B'!T7="","não preenchido",IF(LOWER(TRIM('Revisor B'!T7))=LOWER(TRIM(INDEX(Gabarito!$I:$I,MATCH($A7,Gabarito!$A:$A,0)))),"confere","diverge"))) | K7: =IF('Revisor B'!W7<>"",'Revisor B'!W7,IF('Revisor B'!V7="","não preenchido",IF(LOWER(TRIM('Revisor B'!V7))=LOWER(TRIM(INDEX(Gabarito!$J:$J,MATCH($A7,Gabarito!$A:$A,0)))),"confere","diverge"))) | L7: =IF('Revisor B'!AB7="","não preenchido",'Revisor B'!AB7) | M7: =IF('Revisor B'!AC7="","não preenchido",'Revisor B'!AC7) | N7: =COUNTIF(C7:K7,"diverge") | O7: =IF(COUNTIF(C7:K7,"não preenchido")=9,"não preenchido",IF(N7>0,"diverge","confere")) | P7: =IFERROR(INDEX('Apuração A'!$C$2:$C$101,MATCH($A7,'Apuração A'!$A$2:$A$101,0)),"") | Q7: =IFERROR(INDEX('Apuração A'!$D$2:$D$101,MATCH($A7,'Apuração A'!$A$2:$A$101,0)),"") | R7: =IFERROR(INDEX('Apuração A'!$E$2:$E$101,MATCH($A7,'Apuração A'!$A$2:$A$101,0)),"") | S7: =IFERROR(INDEX('Apuração A'!$F$2:$F$101,MATCH($A7,'Apuração A'!$A$2:$A$101,0)),"") | T7: =IFERROR(INDEX('Apuração A'!$G$2:$G$101,MATCH($A7,'Apuração A'!$A$2:$A$101,0)),"") | U7: =IFERROR(INDEX('Apuração A'!$H$2:$H$101,MATCH($A7,'Apuração A'!$A$2:$A$101,0)),"") | V7: =IFERROR(INDEX('Apuração A'!$I$2:$I$101,MATCH($A7,'Apuração A'!$A$2:$A$101,0)),"") | W7: =IFERROR(INDEX('Apuração A'!$J$2:$J$101,MATCH($A7,'Apuração A'!$A$2:$A$101,0)),"") | X7: =IFERROR(INDEX('Apuração A'!$K$2:$K$101,MATCH($A7,'Apuração A'!$A$2:$A$101,0)),"")
